Running job on Hoffman2 with Job ID: 7845134
Loaded Modules:
Currently Loaded Modulefiles:
 1) python/3.9.6(default)   2) anaconda3/2023.03  

Key:
(symbolic-version)  
Python 3.9.6 and Anaconda3 2023.03 modules loaded

Apptainer loaded successfully!
apptainer version 1.2.2
INFO:    Instance stats will not be available - requires cgroups v2 with systemd as manager.
INFO:    fuse2fs not found, will not be able to mount EXT3 filesystems
INFO:    gocryptfs not found, will not be able to use gocryptfs
INFO:    underlay of /etc/localtime required more than 50 (88) bind mounts
INFO:    underlay of /usr/bin/nvidia-smi required more than 50 (379) bind mounts

INFO:    instance started successfully
Started Apptainer instance: myollama
bpeir    28671 13.0  0.0  25080  1840 ?        R    12:21   0:00 /bin/squashfuse_ll -f -o offset=40960 /proc/self/fd/3 /u/local/apps/apptainer/1.2.2/var/apptainer/mnt/session/rootfs
bpeir    28687  0.0  0.0   9100   680 ?        S    12:21   0:00 grep apptainer
INSTANCE NAME    PID      IP    IMAGE
myollama         28659          /u/local/apps/apptainer/H2_containers/h2-ollama.sif

Conda environment activated successfully

Using Python from: /u/project/tpresner/shared/mypython/bin/python
Python 3.9.21

Flask server started with PID 28711


Processing file: steak.txt
Content:
a steak



Failed to connect to Flask server: HTTPConnectionPool(host='localhost', port=5000): Max retries exceeded with url: /chat (Caused by NewConnectionError('<urllib3.connection.HTTPConnection object at 0x2ae36e5e6100>: Failed to establish a new connection: [Errno 111] Connection refused'))
Client script executed. Output saved to /u/project/tpresner/shared/qsub/practice/bpeir/output
Stopping Flask server with PID 28711
Flask server stopped successfully.
INFO:    Stopping myollama instance of /u/local/apps/apptainer/H2_containers/h2-ollama.sif (PID=28659)
INFO:    Killing myollama instance of /u/local/apps/apptainer/H2_containers/h2-ollama.sif (PID=28659) (Timeout)
myollama apptainer instance stopped.
